2023-12-18 06:39:27,546 ERROR: Exception on /search [GET] [in C:\xampp\htdocs\Python Projects\pythonProject\microblog\venv\Lib\site-packages\flask\app.py:1414]
Traceback (most recent call last):
  File "C:\xampp\htdocs\Python Projects\pythonProject\microblog\venv\Lib\site-packages\flask\app.py", line 2190, in wsgi_app
    response = self.full_dispatch_request()
               ^^^^^^^^^^^^^^^^^^^^^^^^^^^^
  File "C:\xampp\htdocs\Python Projects\pythonProject\microblog\venv\Lib\site-packages\flask\app.py", line 1486, in full_dispatch_request
    rv = self.handle_user_exception(e)
         ^^^^^^^^^^^^^^^^^^^^^^^^^^^^^
  File "C:\xampp\htdocs\Python Projects\pythonProject\microblog\venv\Lib\site-packages\flask\app.py", line 1484, in full_dispatch_request
    rv = self.dispatch_request()
         ^^^^^^^^^^^^^^^^^^^^^^^
  File "C:\xampp\htdocs\Python Projects\pythonProject\microblog\venv\Lib\site-packages\flask\app.py", line 1469, in dispatch_request
    return self.ensure_sync(self.view_functions[rule.endpoint])(**view_args)
           ^^^^^^^^^^^^^^^^^^^^^^^^^^^^^^^^^^^^^^^^^^^^^^^^^^^^^^^^^^^^^^^^^
  File "C:\xampp\htdocs\Python Projects\pythonProject\microblog\venv\Lib\site-packages\flask_login\utils.py", line 290, in decorated_view
    return current_app.ensure_sync(func)(*args, **kwargs)
           ^^^^^^^^^^^^^^^^^^^^^^^^^^^^^^^^^^^^^^^^^^^^^^
  File "C:\xampp\htdocs\Python Projects\pythonProject\Microblog\app\main\routes.py", line 156, in search
    posts, total = Post.search(g.search_form.q.data, page,
                   ^^^^^^^^^^^^^^^^^^^^^^^^^^^^^^^^^^^^^^^
  File "C:\xampp\htdocs\Python Projects\pythonProject\Microblog\app\models.py", line 18, in search
    ids, total = query_index(cls.__tablename__, expression, page, per_page)
                 ^^^^^^^^^^^^^^^^^^^^^^^^^^^^^^^^^^^^^^^^^^^^^^^^^^^^^^^^^^
  File "C:\xampp\htdocs\Python Projects\pythonProject\Microblog\app\search.py", line 22, in query_index
    search = current_app.elasticsearch.search(
             ^^^^^^^^^^^^^^^^^^^^^^^^^^^^^^^^^
  File "C:\xampp\htdocs\Python Projects\pythonProject\microblog\venv\Lib\site-packages\elasticsearch\_sync\client\utils.py", line 402, in wrapped
    return api(*args, **kwargs)
           ^^^^^^^^^^^^^^^^^^^^
  File "C:\xampp\htdocs\Python Projects\pythonProject\microblog\venv\Lib\site-packages\elasticsearch\_sync\client\__init__.py", line 3733, in search
    return self.perform_request(  # type: ignore[return-value]
           ^^^^^^^^^^^^^^^^^^^^^^^^^^^^^^^^^^^^^^^^^^^^^^^^^^^
  File "C:\xampp\htdocs\Python Projects\pythonProject\microblog\venv\Lib\site-packages\elasticsearch\_sync\client\_base.py", line 285, in perform_request
    meta, resp_body = self.transport.perform_request(
                      ^^^^^^^^^^^^^^^^^^^^^^^^^^^^^^^
  File "C:\xampp\htdocs\Python Projects\pythonProject\microblog\venv\Lib\site-packages\elastic_transport\_transport.py", line 328, in perform_request
    meta, raw_data = node.perform_request(
                     ^^^^^^^^^^^^^^^^^^^^^
  File "C:\xampp\htdocs\Python Projects\pythonProject\microblog\venv\Lib\site-packages\elastic_transport\_node\_http_urllib3.py", line 202, in perform_request
    raise err from None
elastic_transport.ConnectionError: Connection error caused by: ConnectionError(Connection error caused by: NewConnectionError(<urllib3.connection.HTTPConnection object at 0x000002678BE30F50>: Failed to establish a new connection: [WinError 10061] No connection could be made because the target machine actively refused it))
2023-12-18 06:57:00,262 INFO: Microblog startup [in C:\xampp\htdocs\Python Projects\pythonProject\Microblog\app\__init__.py:87]
2023-12-18 06:59:53,018 INFO: Microblog startup [in C:\xampp\htdocs\Python Projects\pythonProject\Microblog\app\__init__.py:87]
2023-12-18 07:00:20,960 ERROR: Exception on /search [GET] [in C:\xampp\htdocs\Python Projects\pythonProject\microblog\venv\Lib\site-packages\flask\app.py:1414]
Traceback (most recent call last):
  File "C:\xampp\htdocs\Python Projects\pythonProject\microblog\venv\Lib\site-packages\flask\app.py", line 2190, in wsgi_app
    response = self.full_dispatch_request()
               ^^^^^^^^^^^^^^^^^^^^^^^^^^^^
  File "C:\xampp\htdocs\Python Projects\pythonProject\microblog\venv\Lib\site-packages\flask\app.py", line 1486, in full_dispatch_request
    rv = self.handle_user_exception(e)
         ^^^^^^^^^^^^^^^^^^^^^^^^^^^^^
  File "C:\xampp\htdocs\Python Projects\pythonProject\microblog\venv\Lib\site-packages\flask\app.py", line 1484, in full_dispatch_request
    rv = self.dispatch_request()
         ^^^^^^^^^^^^^^^^^^^^^^^
  File "C:\xampp\htdocs\Python Projects\pythonProject\microblog\venv\Lib\site-packages\flask\app.py", line 1469, in dispatch_request
    return self.ensure_sync(self.view_functions[rule.endpoint])(**view_args)
           ^^^^^^^^^^^^^^^^^^^^^^^^^^^^^^^^^^^^^^^^^^^^^^^^^^^^^^^^^^^^^^^^^
  File "C:\xampp\htdocs\Python Projects\pythonProject\microblog\venv\Lib\site-packages\flask_login\utils.py", line 290, in decorated_view
    return current_app.ensure_sync(func)(*args, **kwargs)
           ^^^^^^^^^^^^^^^^^^^^^^^^^^^^^^^^^^^^^^^^^^^^^^
  File "C:\xampp\htdocs\Python Projects\pythonProject\Microblog\app\main\routes.py", line 156, in search
    posts, total = Post.search(g.search_form.q.data, page,
                   ^^^^^^^^^^^^^^^^^^^^^^^^^^^^^^^^^^^^^^^
  File "C:\xampp\htdocs\Python Projects\pythonProject\Microblog\app\models.py", line 18, in search
    ids, total = query_index(cls.__tablename__, expression, page, per_page)
                 ^^^^^^^^^^^^^^^^^^^^^^^^^^^^^^^^^^^^^^^^^^^^^^^^^^^^^^^^^^
  File "C:\xampp\htdocs\Python Projects\pythonProject\Microblog\app\search.py", line 22, in query_index
    search = current_app.elasticsearch.search(
             ^^^^^^^^^^^^^^^^^^^^^^^^^^^^^^^^^
  File "C:\xampp\htdocs\Python Projects\pythonProject\microblog\venv\Lib\site-packages\elasticsearch\_sync\client\utils.py", line 402, in wrapped
    return api(*args, **kwargs)
           ^^^^^^^^^^^^^^^^^^^^
  File "C:\xampp\htdocs\Python Projects\pythonProject\microblog\venv\Lib\site-packages\elasticsearch\_sync\client\__init__.py", line 3733, in search
    return self.perform_request(  # type: ignore[return-value]
           ^^^^^^^^^^^^^^^^^^^^^^^^^^^^^^^^^^^^^^^^^^^^^^^^^^^
  File "C:\xampp\htdocs\Python Projects\pythonProject\microblog\venv\Lib\site-packages\elasticsearch\_sync\client\_base.py", line 285, in perform_request
    meta, resp_body = self.transport.perform_request(
                      ^^^^^^^^^^^^^^^^^^^^^^^^^^^^^^^
  File "C:\xampp\htdocs\Python Projects\pythonProject\microblog\venv\Lib\site-packages\elastic_transport\_transport.py", line 328, in perform_request
    meta, raw_data = node.perform_request(
                     ^^^^^^^^^^^^^^^^^^^^^
  File "C:\xampp\htdocs\Python Projects\pythonProject\microblog\venv\Lib\site-packages\elastic_transport\_node\_http_urllib3.py", line 202, in perform_request
    raise err from None
elastic_transport.ConnectionError: Connection error caused by: ConnectionError(Connection error caused by: NewConnectionError(<urllib3.connection.HTTPConnection object at 0x0000023C07B4CAD0>: Failed to establish a new connection: [WinError 10061] No connection could be made because the target machine actively refused it))
