2023-12-07 06:09:45,096 ERROR: Exception on /user/frankline [GET] [in C:\xampp\htdocs\Python Projects\pythonProject\microblog\venv\Lib\site-packages\flask\app.py:1414]
Traceback (most recent call last):
  File "C:\xampp\htdocs\Python Projects\pythonProject\microblog\venv\Lib\site-packages\flask\app.py", line 2190, in wsgi_app
    response = self.full_dispatch_request()
               ^^^^^^^^^^^^^^^^^^^^^^^^^^^^
  File "C:\xampp\htdocs\Python Projects\pythonProject\microblog\venv\Lib\site-packages\flask\app.py", line 1486, in full_dispatch_request
    rv = self.handle_user_exception(e)
         ^^^^^^^^^^^^^^^^^^^^^^^^^^^^^
  File "C:\xampp\htdocs\Python Projects\pythonProject\microblog\venv\Lib\site-packages\flask\app.py", line 1484, in full_dispatch_request
    rv = self.dispatch_request()
         ^^^^^^^^^^^^^^^^^^^^^^^
  File "C:\xampp\htdocs\Python Projects\pythonProject\microblog\venv\Lib\site-packages\flask\app.py", line 1469, in dispatch_request
    return self.ensure_sync(self.view_functions[rule.endpoint])(**view_args)
           ^^^^^^^^^^^^^^^^^^^^^^^^^^^^^^^^^^^^^^^^^^^^^^^^^^^^^^^^^^^^^^^^^
  File "C:\xampp\htdocs\Python Projects\pythonProject\microblog\venv\Lib\site-packages\flask_login\utils.py", line 290, in decorated_view
    return current_app.ensure_sync(func)(*args, **kwargs)
           ^^^^^^^^^^^^^^^^^^^^^^^^^^^^^^^^^^^^^^^^^^^^^^
  File "C:\xampp\htdocs\Python Projects\pythonProject\Microblog\app\main\routes.py", line 66, in user
    return render_template('user.html', user=user, posts=posts.items, next_url=next_url,
           ^^^^^^^^^^^^^^^^^^^^^^^^^^^^^^^^^^^^^^^^^^^^^^^^^^^^^^^^^^^^^^^^^^^^^^^^^^^^^
  File "C:\xampp\htdocs\Python Projects\pythonProject\microblog\venv\Lib\site-packages\flask\templating.py", line 151, in render_template
    return _render(app, template, context)
           ^^^^^^^^^^^^^^^^^^^^^^^^^^^^^^^
  File "C:\xampp\htdocs\Python Projects\pythonProject\microblog\venv\Lib\site-packages\flask\templating.py", line 132, in _render
    rv = template.render(context)
         ^^^^^^^^^^^^^^^^^^^^^^^^
  File "C:\xampp\htdocs\Python Projects\pythonProject\microblog\venv\Lib\site-packages\jinja2\environment.py", line 1301, in render
    self.environment.handle_exception()
  File "C:\xampp\htdocs\Python Projects\pythonProject\microblog\venv\Lib\site-packages\jinja2\environment.py", line 936, in handle_exception
    raise rewrite_traceback_stack(source=source)
  File "C:\xampp\htdocs\Python Projects\pythonProject\Microblog\app\templates\user.html", line 1, in top-level template code
    {% extends "base.html" %}
  File "C:\xampp\htdocs\Python Projects\pythonProject\Microblog\app\templates\base.html", line 1, in top-level template code
    {% extends 'bootstrap/base.html' %}
    ^^^^^^^^^^^^^^^^^^^^^^^^^
  File "C:\xampp\htdocs\Python Projects\pythonProject\microblog\venv\Lib\site-packages\flask_bootstrap\templates\bootstrap\base.html", line 1, in top-level template code
    {% block doc -%}
  File "C:\xampp\htdocs\Python Projects\pythonProject\microblog\venv\Lib\site-packages\flask_bootstrap\templates\bootstrap\base.html", line 4, in block 'doc'
    {%- block html %}
  File "C:\xampp\htdocs\Python Projects\pythonProject\microblog\venv\Lib\site-packages\flask_bootstrap\templates\bootstrap\base.html", line 20, in block 'html'
    {% block body -%}
  File "C:\xampp\htdocs\Python Projects\pythonProject\microblog\venv\Lib\site-packages\flask_bootstrap\templates\bootstrap\base.html", line 23, in block 'body'
    {% block content -%}
  File "C:\xampp\htdocs\Python Projects\pythonProject\Microblog\app\templates\base.html", line 48, in block 'content'
    {% block app_content %}{% endblock %}
    ^^^^^^^^^^^^^^^^^^^^^^^^^
  File "C:\xampp\htdocs\Python Projects\pythonProject\Microblog\app\templates\user.html", line 13, in block 'app_content'
    <p>{{ _('%(count)d followers', count=user.followers.count()) }}, {{ _('%(count)d following', count=user.followed.count()) }}</p>
    ^^^^^^^^^^^^^^^^^^^^^^^^^
  File "C:\xampp\htdocs\Python Projects\pythonProject\microblog\venv\Lib\site-packages\jinja2\utils.py", line 83, in from_obj
    if hasattr(obj, "jinja_pass_arg"):
       ^^^^^^^^^^^^^^^^^^^^^^^^^^^^^^
jinja2.exceptions.UndefinedError: 'sqlalchemy.orm.writeonly.WriteOnlyCollection object' has no attribute 'count'
2023-12-07 06:09:54,287 ERROR: Exception on /auth/reset_password_request [POST] [in C:\xampp\htdocs\Python Projects\pythonProject\microblog\venv\Lib\site-packages\flask\app.py:1414]
Traceback (most recent call last):
  File "C:\xampp\htdocs\Python Projects\pythonProject\microblog\venv\Lib\site-packages\flask\app.py", line 2190, in wsgi_app
    response = self.full_dispatch_request()
               ^^^^^^^^^^^^^^^^^^^^^^^^^^^^
  File "C:\xampp\htdocs\Python Projects\pythonProject\microblog\venv\Lib\site-packages\flask\app.py", line 1486, in full_dispatch_request
    rv = self.handle_user_exception(e)
         ^^^^^^^^^^^^^^^^^^^^^^^^^^^^^
  File "C:\xampp\htdocs\Python Projects\pythonProject\microblog\venv\Lib\site-packages\flask\app.py", line 1484, in full_dispatch_request
    rv = self.dispatch_request()
         ^^^^^^^^^^^^^^^^^^^^^^^
  File "C:\xampp\htdocs\Python Projects\pythonProject\microblog\venv\Lib\site-packages\flask\app.py", line 1469, in dispatch_request
    return self.ensure_sync(self.view_functions[rule.endpoint])(**view_args)
           ^^^^^^^^^^^^^^^^^^^^^^^^^^^^^^^^^^^^^^^^^^^^^^^^^^^^^^^^^^^^^^^^^
  File "C:\xampp\htdocs\Python Projects\pythonProject\Microblog\app\auth\routes.py", line 66, in reset_password_request
    send_password_reset_email(user)
  File "C:\xampp\htdocs\Python Projects\pythonProject\Microblog\app\auth\email.py", line 15, in send_password_reset_email
    text_body=render_template('email/reset_password.txt',
              ^^^^^^^^^^^^^^^^^^^^^^^^^^^^^^^^^^^^^^^^^^^
  File "C:\xampp\htdocs\Python Projects\pythonProject\microblog\venv\Lib\site-packages\flask\templating.py", line 151, in render_template
    return _render(app, template, context)
           ^^^^^^^^^^^^^^^^^^^^^^^^^^^^^^^
  File "C:\xampp\htdocs\Python Projects\pythonProject\microblog\venv\Lib\site-packages\flask\templating.py", line 132, in _render
    rv = template.render(context)
         ^^^^^^^^^^^^^^^^^^^^^^^^
  File "C:\xampp\htdocs\Python Projects\pythonProject\microblog\venv\Lib\site-packages\jinja2\environment.py", line 1301, in render
    self.environment.handle_exception()
  File "C:\xampp\htdocs\Python Projects\pythonProject\microblog\venv\Lib\site-packages\jinja2\environment.py", line 936, in handle_exception
    raise rewrite_traceback_stack(source=source)
  File "C:\xampp\htdocs\Python Projects\pythonProject\Microblog\app\templates\email\reset_password.txt", line 5, in top-level template code
    {{ url_for('reset_password', token=token, _external=True) }}
    ^^^^^^^^^^^^^^^^^^^^^^^^^
  File "C:\xampp\htdocs\Python Projects\pythonProject\microblog\venv\Lib\site-packages\flask\app.py", line 1697, in url_for
    return self.handle_url_build_error(error, endpoint, values)
           ^^^^^^^^^^^^^^^^^^^^^^^^^^^^^^^^^^^^^^^^^^^^^^^^^^^^
  File "C:\xampp\htdocs\Python Projects\pythonProject\microblog\venv\Lib\site-packages\flask\app.py", line 1686, in url_for
    rv = url_adapter.build(  # type: ignore[union-attr]
         ^^^^^^^^^^^^^^^^^^^^^^^^^^^^^^^^^^^^^^^^^^^^^^
  File "C:\xampp\htdocs\Python Projects\pythonProject\microblog\venv\Lib\site-packages\werkzeug\routing\map.py", line 917, in build
    raise BuildError(endpoint, values, method, self)
werkzeug.routing.exceptions.BuildError: Could not build url for endpoint 'reset_password' with values ['token']. Did you mean 'auth.reset_password' instead?
2023-12-07 06:12:17,732 INFO: Microblog startup [in C:\xampp\htdocs\Python Projects\pythonProject\Microblog\app\__init__.py:84]
